Workbook

Sheet README
A1: Amyloidosis Multi-Phenotype Bucket-Combination Config Specification
A3: Purpose | B3: Convert all 133 rows from the four pre-test phenotype CSVs into an implementation-ready, non-additive reasoning config.
A4: Core logic | B4: Keep best-tier-per-independent-bucket logic. Tier 1/2 may form approved combinations; Tier 3/4 are context. Never add tiers into a numeric disease score.
A5: Key change | B5: Use phenotype-specific combination configs instead of one universal '2 of ortho/cardio/neuro' ATTR rule.
A6: Source specialty vs reasoning bucket | B6: Source specialty records where evidence came from. Reasoning bucket records the independent biological/clinical axis used by the combination engine.
A7: Deduplication | B7: Canonical_Atom_or_Rule_ID lets repeated concepts across ATTRwt/ATTRv/AL/AA point to one extraction rule rather than duplicate EHR extraction.
A8: Composite rows | B8: Composite/temporal source rows are rules or derived features. They do NOT create an extra independent bucket.
A9: Guardrails | B9: Counter-evidence / differential rows are explicit routes or modifiers, never weak positive Tier 4 evidence.
A10: General amyloidosis | B10: Uses independent bucket combinations before subtype routing. A patient may simultaneously pass ATTR and an AL safety route.
A11: Clinical status | B11: This workbook is a research/EHR feature-design specification derived from the supplied tables, not a validated diagnostic score or clinical decision rule.
A13: Sheet | B13: What it contains | C13: Use in code
A14: Signal Catalog | B14: One row for every source CSV row (133 total), with specialty, reasoning bucket, canonical atom/rule, proposed source tier and disposition.
A15: Phenotype Overlays | B15: Normalized config rows. Every source row has a source-phenotype overlay; positive rows also get GENERAL_AMYLOID and/or ATTR_COMMON overlays.
A16: Combination Rules | B16: Approved non-additive bucket combinations for GENERAL_AMYLOID, ATTR_COMMON, ATTRwt, ATTRv, AL and AA.
A17: Composite Rules | B17: How multi-signal source rows are derived without double-counting.
A18: Temporal Rules | B18: Longitudinal logic such as orthopedic prodrome before cardiac disease and persistent renal/inflammatory trajectories.
A19: Guardrails | B19: Differential routes, alternative-cause flags and do-not-use rows.
A20: Coverage Audit | B20: Formula-driven proof that all rows from all four source CSVs are represented.

Sheet Signal Catalog
A1: Source_Phenotype | B1: Sign_ID | C1: Canonical_Atom_or_Rule_ID | D1: Config_Object_Type | E1: Config_Action | F1: Sign_or_Phenotype_Feature | G1: Source_Domain | H1: Source_Specialty | I1: Reasoning_Bucket | J1: Source_Phenotype_Role | K1: Source_Direction | L1: Proposed_Source_Tier | M1: Source_Gate_Eligible | N1: General_Amyloid_Tier | O1: General_Amyloid_Role | P1: ATTR_Common_Tier | Q1: Differential_Route_or_Guardrail | R1: Typical_Timing_vs_Diagnosis | S1: Combination_from_Source | T1: Threshold_or_Criterion_Status | U1: PreTest_Usability | V1: EHR_Detectability | W1: Likely_EHR_Location | X1: Structured_Fields_or_NLP_Terms | Y1: Recommended_Model_Use_Source | Z1: Key_Overlap_Mimic_Guardrail | AA1: Evidence_Confidence | AB1: Amyloid_Suspicion_Importance_Source | AC1: Subtype_Distinguisher_Importance_Source | AD1: Original_Source_Priority_Tier | AE1: Primary_Source | AF1: Supporting_Source | AG1: Config_Design_Note | AH1: Coverage_Status
A2: ATTRwt | B2: WT01 | C2: RULE_ATTRWT_ORTHO_BEFORE_CARDIO | D2: TEMPORAL_RULE | E2: EVALUATE_TEMPORAL_RULE | F2: Orthopedic/tenosynovial prodrome followed years later by otherwise unexplained cardiac disease | G2: Multisystem / temporal | H2: MULTISPECIALTY | I2: TEMPORAL_COMPOSITE | J2: Core composite discriminator | K2: Strongly supports ATTRwt | M2: No | R2: Musculoskeletal events commonly 5–15 years before cardiac recognition | S2: ?2 orthopedic/soft-tissue clues ? years later new HFpEF/LVH/AF/conduction disease | T2: No validated universal count or time-window rule; 5–15 years is evidence-backed for CTS and broadly consistent with the musculoskeletal prodrome. | U2: Yes | V2: High | W2: Derived from procedures + diagnoses + cardiology | X2: bilateral CTS/CTR; lumbar stenosis/decompression; biceps rupture; arthroplasty; trigger finger; HFpEF; LVH; AF | Y2: Highest-priority composite feature. Model chronology and clustering rather than simple feature count. | Z2: ATTRv can also have CTS; isolated degenerative disease is common; AL can cause cardiac amyloid but lacks this characteristic orthopedic enrichment. | AA2: High | AB2: 5 | AC2: 5 | AD2: Tier 1 - highest | AE2: https://pubmed.ncbi.nlm.nih.gov/36049804/ | AF2: https://pmc.ncbi.nlm.nih.gov/articles/PMC9775219/ | AG2: Composite/temporal rule: do not count as an extra independent bucket. | AH2: =IF(AND(E2<>"",D2<>""),"COVERED","MISSING") -> COVERED
A3: ATTRwt | B3: WT04 | C3: ATOM_WT04 | D3: DERIVED_BUCKET_FEATURE | E3: DERIVE_WITHIN_BUCKET | F3: Multiple orthopedic red flags across different tissues/procedures | G3: Musculoskeletal | H3: ORTHOPEDICS | I3: ORTHO | J3: Composite discriminator / cluster | K3: Strongly supports ATTRwt | L3: Tier 1 | M3: Yes | N3: Tier 2 | O3: ORGAN_OR_PHENOTYPE_EVIDENCE | P3: Tier 1 | R3: Usually years before cardiac diagnosis | S3: Any 2+ of bilateral/recurrent CTS, LSS/decompression, biceps rupture, arthroplasty, trigger finger, shoulder disease + later cardiac clue | T3: No validated minimum feature count; 'multiple' is a research-synthesis construct for prioritization. | U3: Yes | V3: High | W3: Procedures + diagnosis history | X3: multi-joint/tendon procedure history; repeated orthopedic diagnoses | Y3: Core EHR cluster; give more weight to unusual/bilateral/recurrent events and temporal sequence. | Z3: Degenerative disease burden also rises with age; subtype cannot be established from orthopedics alone. | AA3: High | AB3: 4 | AC3: 5 | AD3: Tier 1 - highest | AE3: https://pubmed.ncbi.nlm.nih.gov/41906617/ | AF3: https://pmc.ncbi.nlm.nih.gov/articles/PMC9775219/ | AG3: Detect once using canonical ID; phenotype overlays decide tier/role. | AH3: =IF(AND(E3<>"",D3<>""),"COVERED","MISSING") -> COVERED
A4: ATTRwt | B4: WT02 | C4: ORTHO_CTS_BILAT_RECURRENT | D4: ATOM | E4: DETECT_ONCE | F4: Bilateral and/or recurrent carpal tunnel syndrome, especially recurrence after prior carpal tunnel release | G4: Musculoskeletal / tenosynovial | H4: ORTHOPEDICS | I4: ORTHO | J4: Early extracardiac red flag | K4: Strongly supports ATTRwt | L4: Tier 1 | M4: Yes | N4: Tier 2 | O4: ORGAN_OR_PHENOTYPE_EVIDENCE | P4: Tier 1 | R4: Typically years before cardiac diagnosis | S4: Bilateral/recurrent CTR + later HFpEF/LVH/AF/conduction disease or another orthopedic red flag | T4: Do not use the 21.2% subgroup prevalence as a general PPV; it was a selected subgroup in one screening cohort. | U4: Yes | V4: High | W4: Problem list; hand surgery; procedure history | X4: bilateral carpal tunnel; right+left CTR; recurrent median neuropathy; repeat carpal tunnel release | Y4: Tier-defining extracardiac feature; explicitly distinguish bilateral/recurrent from unilateral CTS. | Z4: CTS is common and can occur in ATTRv; unilateral CTS has poor specificity. | AA4: High | AB4: 4 | AC4: 5 | AD4: Tier 1 - highest | AE4: https://pubmed.ncbi.nlm.nih.gov/36049804/ | AF4: https://pubmed.ncbi.nlm.nih.gov/37555238/ | AG4: Detect once using canonical ID; phenotype overlays decide tier/role. | AH4: =IF(AND(E4<>"",D4<>""),"COVERED","MISSING") -> COVERED
A5: ATTRwt | B5: WT03 | C5: ATOM_WT03 | D5: ATOM | E5: DETECT_ONCE | F5: Spontaneous or trivial-trauma distal biceps tendon rupture / 'Popeye sign' | G5: Musculoskeletal / tendon | H5: ORTHOPEDICS | I5: ORTHO | J5: Early extracardiac red flag | K5: Strongly supports ATTRwt | L5: Tier 1 | M5: Yes | N5: Tier 2 | O5: ORGAN_OR_PHENOTYPE_EVIDENCE | P5: Tier 1 | R5: Median ~5 years before HF diagnosis among patients who recalled onset | S5: Biceps rupture + bilateral CTS or spinal stenosis + unexplained HFpEF/LVH | T5: No universal PPV. The published 66% PPV is prevalence-dependent and should only be treated as a scenario estimate. | U5: Yes | V5: High | W5: Orthopedic notes; surgical history; physical exam | X5: distal biceps rupture; atraumatic biceps rupture; Popeye sign | Y5: Strong positive feature, especially in an appropriate cardiac/orthopedic context. | Z5: Traumatic/degenerative tendon rupture can occur without amyloid; published study came from a referral cohort. | AA5: High | AB5: 4 | AC5: 5 | AD5: Tier 1 - highest | AE5: https://pubmed.ncbi.nlm.nih.gov/28898370/ | AF5: https://pmc.ncbi.nlm.nih.gov/articles/PMC9775219/ | AG5: Detect once using canonical ID; phenotype overlays decide tier/role. | AH5: =IF(AND(E5<>"",D5<>""),"COVERED","MISSING") -> COVERED
A6: ATTRwt | B6: WT05 | C6: ORTHO_LUMBAR_STENOSIS | D6: ATOM | E6: DETECT_ONCE | F6: Lumbar spinal stenosis/decompression, especially with thickened ligamentum flavum and another ATTR clue | G6: Musculoskeletal / spine | H6: ORTHOPEDICS | I6: ORTHO | J6: Early extracardiac red flag | K6: Supports ATTRwt strongly | L6: Tier 2 | M6: Yes | N6: Tier 2 | O6: ORGAN_OR_PHENOTYPE_EVIDENCE | P6: Tier 2 | R6: Often pre-cardiac | S6: LSS/decompression + bilateral CTS or biceps rupture + later cardiac red flag | T6: Do not treat 33–45% deposition estimates from selected surgical series as prevalence of systemic ATTRwt-CM. | U6: Yes | V6: High | W6: Problem list; spine MRI; operative history | X6: lumbar spinal stenosis; laminectomy; decompression; ligamentum flavum hypertrophy | Y6: Moderate-high feature; strongest when surgical and clustered. | Z6: Degenerative LSS is extremely common; localized ligament amyloid does not prove systemic cardiac ATTRwt. | AA6: High | AB6: 4 | AC6: 4.5 | AD6: Tier 1 - highest | AE6: https://pubmed.ncbi.nlm.nih.gov/34053807/ | AF6: https://pubmed.ncbi.nlm.nih.gov/41906617/ | AG6: Detect once using canonical ID; phenotype overlays decide tier/role. | AH6: =IF(AND(E6<>"",D6<>""),"COVERED","MISSING") -> COVERED
A7: ATTRwt | B7: WT11 | C7: ATOM_WT11 | D7: ATOM | E7: DETECT_ONCE | F7: Atrial fibrillation/flutter, especially with LV thickening or orthopedic ATTR clues | G7: Cardiac electrical | H7: CARDIOLOGY | I7: CARDIO | J7: Cardiac red flag / comparative clue | K7: Supports ATTRwt | L7: Tier 2 | M7: Yes | N7: Tier 2 | O7: ORGAN_OR_PHENOTYPE_EVIDENCE | P7: Tier 2 | R7: May precede formal diagnosis | S7: AF + CTS/LSS + HFpEF/LVH or conduction disease | T7: No AF burden threshold is validated for ATTRwt suspicion. | U7: Yes | V7: High | W7: Problem list; ECG | X7: atrial fibrillation; atrial flutter | Y7: Moderate-high feature when paired with other ATTRwt clues. | Z7: AF is very common with aging and valvular disease. | AA7: High | AB7: 4 | AC7: 4 | AD7: Tier 2 - high | AE7: https://medinform.jmir.org/2026/1/e85803 | AF7: https://pubmed.ncbi.nlm.nih.gov/36907828/ | AG7: Detect once using canonical ID; phenotype overlays decide tier/role. | AH7: =IF(AND(E7<>"",D7<>""),"COVERED","MISSING") -> COVERED
A8: ATTRwt | B8: WT09 | C8: CARD_HFPEF_UNEXPLAINED | D8: ATOM | E8: DETECT_ONCE | F8: Unexplained HFpEF / heart failure in an older adult | G8: Cardiac | H8: CARDIOLOGY | I8: CARDIO | J8: High-yield cardiac entry phenotype | K8: Supports ATTRwt/ATTR | L8: Tier 2 | M8: Yes | N8: Tier 1 | O8: ORGAN_OR_PHENOTYPE_EVIDENCE | P8: Tier 2 | R8: Usually near cardiac recognition | S8: HFpEF + bilateral/recurrent CTS/LSS/biceps rupture + AF/conduction disease/LVH | T8: No age cutoff alone mandates amyloid testing; use enriched phenotype rather than age+HFpEF only. | U8: Yes | V8: High | W8: Problem list; cardiology | X8: HFpEF; diastolic HF; heart failure | Y8: High amyloidosis importance, only moderate ATTRwt subtype weight. | Z8: HFpEF is common and AL/ATTRv/non-amyloid disease overlap. | AA8: High | AB8: 5 | AC8: 3.5 | AD8: Tier 2 - high | AE8: https://pubmed.ncbi.nlm.nih.gov/35509173/ | AF8: https://pubmed.ncbi.nlm.nih.gov/35343098/ | AG8: Detect once using canonical ID; phenotype overlays decide tier/role. | AH8: =IF(AND(E8<>"",D8<>""),"COVERED","MISSING") -> COVERED
A9: ATTRwt | B9: WT12 | C9: CARD_CONDUCTION_PACEMAKER | D9: ATOM | E9: DETECT_ONCE | F9: Conduction disease (AV block, bundle branch block, sinus-node disease) and/or pacemaker implantation | G9: Cardiac electrical | H9: CARDIOLOGY | I9: CARDIO | J9: Cardiac red flag | K9: Supports ATTRwt/ATTR | L9: Tier 2 | M9: Yes | N9: Tier 1 | O9: ORGAN_OR_PHENOTYPE_EVIDENCE | P9: Tier 2 | R9: May precede or coincide with diagnosis | S9: Pacemaker/AV block + CTS/LSS + LVH/HFpEF | T9: Do not use 40–44% pacemaker prevalence as a general-population screening yield; it reflects diagnosed ATTRwt cohorts. | U9: Yes | V9: High | W9: ECG; device/procedure table | X9: AV block; RBBB/LBBB; sick sinus syndrome; pacemaker | Y9: Moderate-high ATTRwt feature in a multi-domain cluster. | Z9: Age-related conduction disease is common; ATTRv can also cause conduction disease. | AA9: High | AB9: 4.5 | AC9: 4 | AD9: Tier 2 - high | AE9: https://pubmed.ncbi.nlm.nih.gov/33825853/ | AF9: https://pubmed.ncbi.nlm.nih.gov/35509173/ | AG9: Detect once using canonical ID; phenotype overlays decide tier/role. | AH9: =IF(AND(E9<>"",D9<>""),"COVERED","MISSING") -> COVERED
A10: ATTRwt | B10: WT20 | C10: ATOM_WT20 | D10: ATOM | E10: DETECT_ONCE | F10: Incidental myocardial uptake on bone-avid scintigraphy performed for a NON-amyloidosis indication | G10: Incidental imaging | H10: GENERAL MEDICINE | I10: SYSTEMIC_CONTEXT | J10: Incidental high-yield clue | K10: Strongly supports ATTR cardiac amyloidosis | L10: Tier 1 | M10: No — modifier/context only | N10: Tier 1 | O10: MODIFIER | P10: Tier 1 | R10: Potentially pre-symptomatic/incidental | S10: Incidental uptake + orthopedic/cardio ATTR phenotype | T10: Only count if scan was genuinely ordered for another reason. Do not treat as phenotype if PYP/DPD was ordered because amyloid was already suspected. | U10: Only if ordered independently of amyloid work-up | V10: Moderate | W10: Nuclear medicine report | X10: incidental cardiac uptake; myocardial tracer retention on bone scan | Y10: Very high actionability; separate incidental finding from amyloid-specific diagnostic testing. | Z10: Once deliberately ordered for amyloidosis it is no longer a pre-test sign. AL exclusion and proper diagnostic interpretation remain mandatory. | AA10: High | AB10: 5 | AC10: 4.5 | AD10: Tier 2 - high | AE10: https://pubmed.ncbi.nlm.nih.gov/35509173/ | AF10: https://pubmed.ncbi.nlm.nih.gov/33825853/ | AG10: Detect once using canonical ID; phenotype overlays decide tier/role. | AH10: =IF(AND(E10<>"",D10<>""),"COVERED","MISSING") -> COVERED
A11: ATTRwt | B11: WT10 | C11: CARD_LV_THICKENING_UNEXPLAINED | D11: ATOM | E11: DETECT_ONCE | F11: Unexplained LV wall thickening / increased relative wall thickness / non-dilated LV on routine echocardiography | G11: Cardiac imaging | H11: CARDIOLOGY | I11: CARDIO | J11: Cardiac red flag | K11: Supports cardiac amyloidosis; ATTRwt possible | L11: Tier 1 | M11: Yes | N11: Tier 1 | O11: ORGAN_OR_PHENOTYPE_EVIDENCE | P11: Tier 1 | R11: Near cardiac presentation, sometimes incidental | S11: LV thickening/RWT + orthopedic prodrome + AF/conduction disease | T11: Do NOT hard-code a universal 11-mm female threshold. Use sex/body-size-aware LVMI or lower suspicion threshold; evidence for exact cutoff remains limited. | U11: Yes if obtained for routine care | V11: High | W11: Echo report | X11: IVST; posterior wall thickness; LVMI; relative wall thickness; small LV cavity | Y11: High cardiac-amyloid trigger, moderate subtype discriminator. Preserve female sensitivity. | Z11: Hypertension, HCM, AS, AL and ATTRv overlap substantially. | AA11: High | AB11: 5 | AC11: 3.5 | AD11: Tier 3 - moderate | AE11: https://pubmed.ncbi.nlm.nih.gov/35343098/ | AF11: https://pubmed.ncbi.nlm.nih.gov/41752875/ | AG11: Detect once using canonical ID; phenotype overlays decide tier/role. | AH11: =IF(AND(E11<>"",D11<>""),"COVERED","MISSING") -> COVERED
A12: ATTRwt | B12: WT13 | C12: ATOM_WT13 | D12: ATOM | E12: DETECT_ONCE | F12: Late-onset HCM phenotype / asymmetric septal hypertrophy without a convincing sarcomeric explanation | G12: Cardiac imaging / diagnostic history | H12: CARDIOLOGY | I12: CARDIO | J12: Cardiac red flag / mimic | K12: Supports cardiac amyloidosis; ATTRwt often found | L12: Tier 1 | M12: Yes | N12: Tier 1 | O12: ORGAN_OR_PHENOTYPE_EVIDENCE | P12: Tier 1 | R12: At or before amyloid recognition | S12: Late-onset HCM + CTS/LSS/AF/conduction disease or low-voltage/mass discordance | T12: No universal age cutoff; evidence specifically says age should raise suspicion but does not mandate testing alone. | U12: Yes | V12: High | W12: Problem list; echo/CMR | X12: HCM; asymmetric septal hypertrophy; basal septal hypertrophy | Y12: High-value cardiac-mimic trigger in older adults. | Z12: Sarcomeric HCM and hypertensive remodeling remain common; cohort was referral-enriched. | AA12: High | AB12: 4.5 | AC12: 4 | AD12: Tier 3 - moderate | AE12: https://pubmed.ncbi.nlm.nih.gov/31371117/ | AF12: https://pubmed.ncbi.nlm.nih.gov/35343098/ | AG12: Detect once using canonical ID; phenotype overlays decide tier/role. | AH12: =IF(AND(E12<>"",D12<>""),"COVERED","MISSING") -> COVERED
A13: ATTRwt | B13: WT06 | C13: ATOM_WT06 | D13: ATOM | E13: DETECT_ONCE | F13: Hip or knee arthroplasty years before cardiac disease, especially multiple/bilateral large-joint replacements | G13: Musculoskeletal / joint | H13: ORTHOPEDICS | I13: ORTHO | J13: Supporting extracardiac red flag | K13: Supports ATTR/ATTRwt | L13: Tier 3 | M13: No | N13: Tier 3 | O13: ORGAN_OR_PHENOTYPE_EVIDENCE | P13: Tier 3 | R13: Mean ~7 years before ATTR cardiac diagnosis in one cohort | S13: Multiple/bilateral arthroplasties + CTS/LSS + later HFpEF/LVH | T13: No validated arthroplasty count or latency threshold for ATTRwt. | U13: Yes | V13: High | W13: Procedure history; orthopedic notes | X13: THA; TKA; total hip replacement; total knee replacement; bilateral arthroplasty | Y13: Supportive cluster feature; do not rank as highly as bilateral/recurrent CTS or biceps rupture. | Z13: Evidence was ATTR broadly, not strictly ATTRwt; arthroplasty is common from osteoarthritis. | AA13: Moderate-High | AB13: 3 | AC13: 4 | AD13: Tier 3 - moderate | AE13: https://pubmed.ncbi.nlm.nih.gov/28906148/ | AF13: https://pmc.ncbi.nlm.nih.gov/articles/PMC9775219/ | AG13: Detect once using canonical ID; phenotype overlays decide tier/role. | AH13: =IF(AND(E13<>"",D13<>""),"COVERED","MISSING") -> COVERED
A14: ATTRwt | B14: WT14 | C14: ATOM_WT14 | D14: ATOM | E14: DETECT_ONCE | F14: Severe aortic stenosis, particularly low-flow/low-gradient AS with additional amyloid red flags | G14: Cardiac / valvular | H14: CARDIOLOGY | I14: CARDIO | J14: High-risk population | K14: Supports ATTR-CM; ATTRwt plausible | L14: Tier 2 | M14: Yes | N14: Tier 2 | O14: ORGAN_OR_PHENOTYPE_EVIDENCE | P14: Tier 2 | R14: At valve evaluation / TAVR work-up | S14: Severe AS + CTS/LSS/AF/conduction disease + disproportionate wall thickening/low flow | T14: Do not hard-code '30% in low-flow low-gradient' as universal; estimates vary by cohort and selection. | U14: Yes | V14: High | W14: Problem list; echo; valve clinic | X14: severe AS; low-flow low-gradient; TAVR/SAVR | Y14: Population-enrichment feature, not a subtype-defining sign. | Z14: AS itself causes LVH/HF and is common in the elderly; not wild-type-specific. | AA14: High | AB14: 4 | AC14: 3 | AD14: Tier 3 - moderate | AE14: https://pubmed.ncbi.nlm.nih.gov/33181246/ | AF14: https://pubmed.ncbi.nlm.nih.gov/38367883/ | AG14: Detect once using canonical ID; phenotype overlays decide tier/role. | AH14: =IF(AND(E14<>"",D14<>""),"COVERED","MISSING") -> COVERED
... A23: ATTRwt | B23: WT21 | C23: ATOM_WT21 | D23: ATOM | E23: DETECT_ONCE | F23: Bilateral sensorineural hearing loss greater than expected for age | G23: Neurologic / sensory | H23: NEUROLOGY | I23: NEURO | J23: Supporting extracardiac clue | K23: Supports ATTRwt modestly | L23: Tier 3 | M23: No | N23: Tier 4 | O23: ORGAN_OR_PHENOTYPE_EVIDENCE | P23: Tier 3 | R23: May precede cardiac recognition | S23: Hearing loss + CTS/LSS + cardiac phenotype | T23: No validated audiometric threshold for ATTRwt suspicion. | U23: Yes | V23: Moderate | W23: Audiology; ENT notes | X23: sensorineural hearing loss; bilateral hearing aids; presbycusis disproportionate | Y23: Low-moderate cluster enhancer only. | Z23: Presbycusis is extremely common; original ATTRwt study was very small. Exact 5.1-year lead time is not robust enough for universal use. | AA23: Moderate-Low | AB23: 2.5 | AC23: 3 | AD23: Tier 4 - low | AE23: https://pubmed.ncbi.nlm.nih.gov/28598686/ | AF23: https://pubmed.ncbi.nlm.nih.gov/41906617/ | AG23: Detect once using canonical ID; phenotype overlays decide tier/role. | AH23: =IF(AND(E23<>"",D23<>""),"COVERED","MISSING") -> COVERED
A24: ATTRwt | B24: WT24 | C24: RULE_WT24 | D24: GUARDRAIL_ROUTE | E24: ROUTE_OR_MODIFY_INTERPRETATION | F24: Female patient with ATTR-like phenotype despite septal wall thickness <12 mm | G24: Sex-specific cardiac imaging | H24: CARDIOLOGY | I24: CARDIO | J24: False-negative guardrail | K24: ATTRwt remains possible | M24: No | Q24: NO_EXCLUSION_FEMALE_WALL_THICKNESS | R24: At cardiac presentation | S24: Female + HFpEF/AF/CTS/LSS + increased LVMI/RWT even if IVST <12 mm | T24: Do NOT hard-code ?11 mm as a validated female cutoff; use sex-specific LVMI/body-size-aware interpretation and broader red flags. | U24: Yes | V24: High | W24: Demographics + echo | X24: IVST; LVMI; RWT; female sex | Y24: Guardrail against false-negative screening rather than a positive sign. | Z24: Small cohort; exact best threshold needs validation. | AA24: Moderate-High | AB24: 4 | AC24: 3.5 | AD24: Guardrail / differential | AE24: https://pubmed.ncbi.nlm.nih.gov/41752875/ | AF24: https://pubmed.ncbi.nlm.nih.gov/35343098/ | AG24: Guardrail/route: never treat as weak positive Tier 4. | AH24: =IF(AND(E24<>"",D24<>""),"COVERED","MISSING") -> COVERED
A25: ATTRwt | B25: WT22 | C25: ATOM_WT22 | D25: ATOM | E25: DETECT_ONCE | F25: Mild-to-moderate length-dependent sensory polyneuropathy in an otherwise ATTRwt-like older cardiac/orthopedic phenotype | G25: Neurologic | H25: NEUROLOGY | I25: NEURO | J25: Supporting extracardiac clue / subtype guardrail | K25: ATTRwt remains possible | L25: Tier 3 | M25: No | N25: Tier 4 | O25: ORGAN_OR_PHENOTYPE_EVIDENCE | P25: Tier 3 | R25: Usually with established systemic/cardio phenotype | S25: Mild sensory PN + strong orthopedic/cardio ATTRwt cluster and no hereditary red flags | T25: No neuropathy severity threshold defines ATTRwt. | U25: Yes | V25: High | W25: Neurology; EMG; problem list | X25: sensory polyneuropathy; axonal neuropathy; numbness | Y25: Low-moderate positive/compatibility feature; subtype interpretation depends on phenotype severity. | Z25: Prominent painful small-fiber neuropathy, severe dysautonomia, GI failure, ocular signs or family history shift strongly toward ATTRv; AL also causes neuropathy. | AA25: Moderate | AB25: 2.5 | AC25: 2.5 | AD25: Guardrail / differential | AE25: https://pubmed.ncbi.nlm.nih.gov/34994254/ | AF25: https://pubmed.ncbi.nlm.nih.gov/36644836/ | AG25: Detect once using canonical ID; phenotype overlays decide tier/role. | AH25: =IF(AND(E25<>"",D25<>""),"COVERED","MISSING") -> COVERED
A26: ATTRwt | B26: WT30 | C26: ATOM_WT30 | D26: DO_NOT_USE | E26: RETAIN_FOR_AUDIT_ONLY | F26: Elevated serum uric acid | G26: Metabolic laboratory | H26: ENDOCRINE / METABOLIC | I26: SYSTEMIC_CONTEXT | J26: Prognostic marker — not recommended as suspicion feature | K26: Very weak ATTRwt support; prognostic only | M26: No | Q26: NONE_DO_NOT_USE | R26: At established cardiac disease | S26: Do not use for positive suspicion; at most retain for prognosis/severity research | T26: No validated pre-test cutoff for ATTRwt suspicion. | U26: Yes | V26: High | W26: Chemistry lab | X26: serum uric acid; urate | Y26: Tier 5 / weak. Exclude from positive screening score unless a future comparative prediagnosis study demonstrates discrimination. | Z26: CKD, diuretics, gout, metabolic syndrome and HF commonly elevate uric acid. | AA26: Moderate-High | AB26: 1.5 | AC26: 1 | AD26: Tier 5 - weak | AE26: https://pubmed.ncbi.nlm.nih.gov/31825676/ | AF26: https://pubmed.ncbi.nlm.nih.gov/26660282/ | AG26: Retain only for audit/research; do not use as a positive screening trigger. | AH26: =IF(AND(E26<>"",D26<>""),"COVERED","MISSING") -> COVERED
A27: ATTRwt | B27: WT25 | C27: HEME_MGUS | D27: GUARDRAIL_ROUTE | E27: ROUTE_OR_MODIFY_INTERPRETATION | F27: Monoclonal gammopathy / MGUS in an otherwise ATTRwt-like phenotype | G27: Hematology / differential | H27: HEMATOLOGY | I27: HEME_CLONAL | J27: Subtype guardrail | K27: Does not exclude ATTRwt; raises AL concern | M27: No | Q27: AL_SAFETY | R27: At or before amyloid evaluation | S27: MGUS + strong orthopedic/cardio ATTR phenotype ? keep both AL and ATTR in differential | T27: Do not treat MGUS as ATTRwt-positive evidence. It is a differential guardrail and changes the diagnostic pathway. | U27: Only if already known | V27: High | W27: Hematology history; lab results | X27: MGUS; M-spike; monoclonal gammopathy; immunofixation | Y27: Guardrail only; low positive-ranking multiplier but high clinical importance. | Z27: AL is urgent and must be actively excluded. Presence of monoclonal protein invalidates simple non-invasive ATTR attribution and usually requires definitive typing in the clinical pathway. | AA27: High | AB27: 4 | AC27: 1.5 | AD27: Guardrail / differential | AE27: https://pubmed.ncbi.nlm.nih.gov/29424556/ | AF27: https://pubmed.ncbi.nlm.nih.gov/33825853/ | AG27: Guardrail/route: never treat as weak positive Tier 4. | AH27: =IF(AND(E27<>"",D27<>""),"COVERED","MISSING") -> COVERED
A28: ATTRwt | B28: WT26 | C28: RULE_WT26 | D28: GUARDRAIL_ROUTE | E28: ROUTE_OR_MODIFY_INTERPRETATION | F28: Abnormal serum free-light-chain ratio in CKD that may reflect renal clearance rather than monoclonality | G28: Renal / hematology | H28: HEMATOLOGY | I28: HEME_CLONAL | J28: Subtype guardrail | K28: Does not exclude ATTRwt; may be CKD-related FLC shift | M28: No | Q28: AL_SAFETY_INTERPRET_FLC_WITH_CKD | R28: At differential work-up or incidental monoclonal testing | S28: CKD + mild FLC-ratio shift + negative/discordant monoclonal evidence + strong ATTR phenotype | T28: CORRECTION: do not use one blanket 0.54–3.30 range for all eGFR ?45. Use assay- and eGFR-specific reference data. | U28: Only if already known | V28: High | W28: Chemistry + hematology lab | X28: eGFR; kappa; lambda; FLC ratio | Y28: Guardrail; not ATTRwt-positive evidence. | Z28: Assay-specific reference ranges matter; true AL can coexist with CKD; immunofixation context remains essential. | AA28: High | AB28: 3.5 | AC28: 1.5 | AD28: Guardrail / differential | AE28: https://pubmed.ncbi.nlm.nih.gov/36100605/ | AF28: https://pubmed.ncbi.nlm.nih.gov/29424556/ | AG28: Guardrail/route: never treat as weak positive Tier 4. | AH28: =IF(AND(E28<>"",D28<>""),"COVERED","MISSING") -> COVERED
A29: ATTRwt | B29: WT27 | C29: RULE_AL_ORIENTED_MULTISYSTEM | D29: GUARDRAIL_ROUTE | E29: ROUTE_OR_MODIFY_INTERPRETATION | F29: Nephrotic-range proteinuria/marked hypoalbuminemia, macroglossia/periorbital purpura, or strong plasma-cell-disorder context | G29: Renal / mucocutaneous / hematology | H29: HEMATOLOGY | I29: MULTISYSTEM_COMPOSITE | J29: Counter-evidence / AL differential | K29: Raises AL concern | M29: No | Q29: AL | R29: Before/at systemic presentation | S29: Heavy proteinuria + clonal/mucocutaneous AL pattern ? prioritize AL exclusion | T29: No absolute exclusion; this is a strong directional counter-signal. | U29: Yes | V29: High | W29: Labs; problem list; exam notes | X29: nephrotic syndrome; proteinuria; hypoalbuminemia; macroglossia; periorbital purpura; myeloma | Y29: ATTRwt down-weight / urgent AL guardrail. | Z29: MGUS can coexist with ATTRwt, so subtype must remain unresolved until appropriate typing; renal disease can have non-amyloid causes. | AA29: High | AB29: 5 | AC29: 1 | AD29: Guardrail / differential | AE29: https://medinform.jmir.org/2026/1/e85803 | AF29: https://pubmed.ncbi.nlm.nih.gov/29424556/ | AG29: Guardrail/route: never treat as weak positive Tier 4. | AH29: =IF(AND(E29<>"",D29<>""),"COVERED","MISSING") -> COVERED
A30: ATTRwt | B30: WT28 | C30: RULE_ATTRV_NEURO_AUTONOMIC | D30: GUARDRAIL_ROUTE | E30: ROUTE_OR_MODIFY_INTERPRETATION | F30: Prominent painful polyneuropathy with marked dysautonomia/GI dysfunction ± family history or ocular signs | G30: Neurologic / autonomic / hereditary | H30: AUTONOMIC / NEUROLOGY | I30: MULTISYSTEM_COMPOSITE | J30: Counter-evidence / ATTRv differential | K30: Points toward ATTRv | M30: No | Q30: ATTRv | R30: Often earlier in ATTRv than classic ATTRwt cardiomyopathy | S30: Painful/axonal PN + orthostasis/GI/weight loss + family/ocular signs | T30: Family history is supportive but absence does not exclude ATTRv; age does not establish wild-type. | U30: Yes | V30: High | W30: Neurology; GI; family history | X30: small-fiber neuropathy; dysautonomia; orthostasis; diarrhea/constipation; vitreous opacities; family neuropathy | Y30: Strong ATTRwt down-weight / ATTRv guardrail. | Z30: ATTRwt can have some neuropathy/orthostasis, but severe or early autonomic/mixed phenotype shifts toward ATTRv. | AA30: High | AB30: 4.5 | AC30: 1 | AD30: Guardrail / differential | AE30: https://pubmed.ncbi.nlm.nih.gov/31907599/ | AF30: https://pubmed.ncbi.nlm.nih.gov/36644836/ | AG30: Guardrail/route: never treat as weak positive Tier 4. | AH30: =IF(AND(E30<>"",D30<>""),"COVERED","MISSING") -> COVERED
A31: ATTRwt | B31: WT29 | C31: RULE_AA_DRIVER_PLUS_RENAL | D31: GUARDRAIL_ROUTE | E31: ROUTE_OR_MODIFY_INTERPRETATION | F31: Chronic inflammatory/autoinflammatory disease or chronic infection + persistent inflammatory burden + heavy proteinuria | G31: Inflammatory / renal | H31: NEPHROLOGY | I31: MULTISYSTEM_COMPOSITE | J31: Counter-evidence / AA differential | K31: Points toward AA | M31: No | Q31: AA | R31: After sustained inflammatory disease | S31: Persistent inflammatory disease + CRP/SAA burden + proteinuria/nephrotic syndrome | T31: No single inflammation duration threshold; use chronicity/activity plus renal transition. | U31: Yes | V31: High | W31: Problem list; labs; rheumatology/infectious disease | X31: FMF; RA; Crohn; TB; bronchiectasis; CRP/SAA; proteinuria | Y31: ATTRwt down-weight / AA guardrail. | Z31: Older patients may have both degenerative cardiac disease and inflammatory illness; renal cause may remain unresolved. | AA31: High | AB31: 4.5 | AC31: 1 | AD31: Guardrail / differential | AE31: https://pubmed.ncbi.nlm.nih.gov/36759076/ | AF31: https://pubmed.ncbi.nlm.nih.gov/31766892/ | AG31: Guardrail/route: never treat as weak positive Tier 4. | AH31: =IF(AND(E31<>"",D31<>""),"COVERED","MISSING") -> COVERED
A32: ATTRv | B32: V02 | C32: ATOM_V02 | D32: ATOM | E32: DETECT_ONCE | F32: Progressive length-dependent axonal sensorimotor polyneuropathy | G32: Neurologic | H32: NEUROLOGY | I32: NEURO | J32: Core neurologic phenotype | K32: Strongly supports ATTRv | L32: Tier 1 | M32: Yes | N32: Tier 1 | O32: ORGAN_OR_PHENOTYPE_EVIDENCE | P32: Tier 1 | R32: Often the first recognized manifestation | S32: Progressive axonal PN + autonomic/GI/cardiac/family/ocular red flag | T32: No single NCS threshold is diagnostic; progression and phenotype matter. | U32: Yes | V32: High | W32: Neurology notes; diagnosis table; EMG/NCS reports | X32: axonal polyneuropathy; sensorimotor neuropathy; length-dependent neuropathy | Y32: Core high-weight feature; use with red-flag enrichment rather than alone. | Z32: Diabetes, alcohol, nutritional deficiency, toxic neuropathy, AL, CIDP and idiopathic axonal neuropathy can mimic. | AA32: High | AB32: 5 | AC32: 5 | AD32: Tier 1 - highest | AE32: https://pubmed.ncbi.nlm.nih.gov/31907599/ | AF32: https://pubmed.ncbi.nlm.nih.gov/35730447/ | AG32: Detect once using canonical ID; phenotype overlays decide tier/role. | AH32: =IF(AND(E32<>"",D32<>""),"COVERED","MISSING") -> COVERED
A33: ATTRv | B33: V03 | C33: RULE_V03 | D33: COMPOSITE_RULE | E33: EVALUATE_CROSS_BUCKET_RULE | F33: Idiopathic axonal polyneuropathy plus ?2 ATTRv systemic red flags | G33: Neurologic / multisystem | H33: MULTISPECIALTY | I33: MULTISYSTEM_COMPOSITE | J33: High-priority screening cluster | K33: Strongly supports ATTRv | M33: No | R33: Before genetic confirmation | S33: PN + ?2 of family history, bilateral/recurrent CTS, dysautonomia, GI disease, cardiac disease, ocular signs or renal abnormalities | T33: Use the published ?2-red-flag structure as a research heuristic, not a universal diagnostic cutoff. | U33: Yes | V33: High | W33: Derived from diagnoses, family history, notes, cardiology/GI/ophthalmology data | X33: idiopathic axonal neuropathy; red flags; multisystem | Y33: Core review-priority phenotype. | Z33: Yield is referral- and geography-dependent; the 10% figure is not a universal prevalence estimate. | AA33: High | AB33: 5 | AC33: 5 | AD33: Tier 1 - highest | AE33: https://pubmed.ncbi.nlm.nih.gov/37725003/ | AF33: https://pubmed.ncbi.nlm.nih.gov/26663427/ | AG33: Composite/temporal rule: do not count as an extra independent bucket. | AH33: =IF(AND(E33<>"",D33<>""),"COVERED","MISSING") -> COVERED
A34: ATTRv | B34: V04 | C34: ATOM_V04 | D34: ATOM | E34: DETECT_ONCE | F34: Painful small-fiber neuropathy / burning feet with early pain-temperature loss | G34: Neurologic | H34: NEUROLOGY | I34: NEURO | J34: Core neurologic phenotype | K34: Strongly supports ATTRv | L34: Tier 1 | M34: Yes | N34: Tier 1 | O34: ORGAN_OR_PHENOTYPE_EVIDENCE | P34: Tier 1 | R34: Often early, before major weakness | S34: Painful small-fiber PN + dysautonomia/GI symptoms/family history | T34: Routine NCS can be normal early; do not require large-fiber abnormalities. | U34: Yes | V34: High | W34: Neurology notes; symptom NLP; skin/small-fiber testing if done | X34: burning feet; small fiber neuropathy; pain-temperature loss | Y34: Strong positive neurologic feature, especially with multisystem enrichment. | Z34: Diabetic and idiopathic small-fiber neuropathy are common mimics; AL can also cause painful/autonomic neuropathy. | AA34: High | AB34: 5 | AC34: 5 | AD34: Tier 1 - highest | AE34: https://pubmed.ncbi.nlm.nih.gov/31907599/ | AF34: https://pubmed.ncbi.nlm.nih.gov/37869146/ | AG34: Detect once using canonical ID; phenotype overlays decide tier/role. | AH34: =IF(AND(E34<>"",D34<>""),"COVERED","MISSING") -> COVERED
A35: ATTRv | B35: V06 | C35: RULE_V06 | D35: COMPOSITE_RULE | E35: EVALUATE_CROSS_BUCKET_RULE | F35: Mixed neurologic + cardiac phenotype | G35: Multisystem | H35: MULTISPECIALTY | I35: MULTISYSTEM_COMPOSITE | J35: Composite discriminator / cluster | K35: Strongly supports ATTRv | M35: No | R35: May evolve over years | S35: Progressive PN/dysautonomia + LVH/HFpEF/arrhythmia ± family history | T35: No universal combination score is validated. | U35: Yes | V35: High | W35: Derived from neurology + cardiology data | X35: neuropathy + cardiomyopathy; mixed phenotype | Y35: Core subtype-discrimination construct. | Z35: AL is also multisystem; renal/plasma-cell clues should redirect toward AL. | AA35: High | AB35: 5 | AC35: 5 | AD35: Tier 1 - highest | AE35: https://pubmed.ncbi.nlm.nih.gov/38844302/ | AF35: https://pubmed.ncbi.nlm.nih.gov/35730447/ | AG35: Composite/temporal rule: do not count as an extra independent bucket. | AH35: =IF(AND(E35<>"",D35<>""),"COVERED","MISSING") -> COVERED
A36: ATTRv | B36: V05 | C36: ATOM_V05 | D36: ATOM | E36: DETECT_ONCE | F36: Early autonomic dysfunction / dysautonomia | G36: Autonomic neurologic | H36: AUTONOMIC / NEUROLOGY | I36: AUTONOMIC | J36: Early autonomic red flag | K36: Strongly supports ATTRv | L36: Tier 1 | M36: Yes | N36: Tier 1 | O36: ORGAN_OR_PHENOTYPE_EVIDENCE | P36: Tier 1 | R36: Can be first manifestation | S36: Dysautonomia + progressive neuropathy + GI/weight loss/family or cardiac clues | T36: No universal autonomic score threshold for general screening. | U36: Yes | V36: High | W36: Neurology; cardiology; GI/urology notes | X36: dysautonomia; autonomic neuropathy; sweating abnormality | Y36: Core positive feature; subtype value rises when autonomic involvement is early and multi-domain. | Z36: AL, diabetes, Parkinsonian disorders and medications can also cause dysautonomia. | AA36: High | AB36: 5 | AC36: 5 | AD36: Tier 1 - highest | AE36: https://pubmed.ncbi.nlm.nih.gov/31473866/ | AF36: https://pubmed.ncbi.nlm.nih.gov/31907599/ | AG36: Detect once using canonical ID; phenotype overlays decide tier/role. | AH36: =IF(AND(E36<>"",D36<>""),"COVERED","MISSING") -> COVERED
A37: ATTRv | B37: V14 | C37: ATOM_V14 | D37: ATOM | E37: DETECT_ONCE | F37: Prior CIDP diagnosis with poor/absent IVIG or immunotherapy response | G37: Neurologic | H37: NEUROLOGY | I37: NEURO | J37: Misdiagnosis red flag | K37: Strongly supports ATTRv | L37: Tier 1 | M37: Yes | N37: Tier 2 | O37: ORGAN_OR_PHENOTYPE_EVIDENCE | P37: Tier 1 | R37: Before correct diagnosis | S37: CIDP label + distal axonal/progressive course + autonomic/GI/cardiac/CTS clues | T37: No number-of-IVIG-cycles threshold is validated. | U37: Yes | V37: High | W37: Neurology notes; infusion/medication history | X37: CIDP; IVIG; refractory; no response; steroid nonresponse | Y37: High-priority review trigger, not proof of ATTRv. | Z37: True refractory CIDP exists; a 2025 red-flag screening study showed red flags alone have limited specificity. | AA37: High | AB37: 4 | AC37: 5 | AD37: Tier 1 - highest | AE37: https://pubmed.ncbi.nlm.nih.gov/28188196/ | AF37: https://pubmed.ncbi.nlm.nih.gov/40670759/ | AG37: Detect once using canonical ID; phenotype overlays decide tier/role. | AH37: =IF(AND(E37<>"",D37<>""),"COVERED","MISSING") -> COVERED
A38: ATTRv | B38: V15 | C38: ATOM_V15 | D38: ATOM | E38: DETECT_ONCE | F38: Vitreous opacities / amyloid vitreopathy / unexplained recurrent dark floaters confirmed by ophthalmology | G38: Ocular | H38: OPHTHALMOLOGY | I38: OCULAR | J38: Strong subtype clue | K38: Strongly supports ATTRv | L38: Tier 1 | M38: Yes | N38: Tier 2 | O38: ORGAN_OR_PHENOTYPE_EVIDENCE | P38: Tier 1 | R38: Variable; may precede other systemic recognition in ocular-prone variants | S38: Vitreous opacities + neuropathy/family history/scalloped pupil | T38: No universal prevalence or symptom-only diagnostic criterion across variants. | U38: Yes | V38: Moderate | W38: Ophthalmology notes; procedure history | X38: vitreous opacities; vitreopathy; dark floaters | Y38: High subtype discriminator when objectively documented. | Z38: Common benign floaters are not equivalent; ophthalmologist documentation matters. | AA38: High | AB38: 4 | AC38: 5 | AD38: Tier 1 - highest | AE38: https://pubmed.ncbi.nlm.nih.gov/42078187/ | AF38: https://pubmed.ncbi.nlm.nih.gov/20301373/ | AG38: Detect once using canonical ID; phenotype overlays decide tier/role. | AH38: =IF(AND(E38<>"",D38<>""),"COVERED","MISSING") -> COVERED
A39: ATTRv | B39: V07 | C39: ATOM_V07 | D39: ATOM | E39: DETECT_ONCE | F39: First-degree family history of genetically or clinically established ATTR amyloidosis | G39: Genetic / family | H39: GENETICS / FAMILY HISTORY | I39: HEREDITARY | J39: Background risk | K39: Strongly supports ATTRv | L39: Tier 1 | M39: Yes | N39: Tier 2 | O39: ETIOLOGIC_CONTEXT | P39: Tier 1 | R39: Can precede symptoms by decades | S39: Family history + any compatible neuropathy/autonomic/cardiac/ocular sign | T39: No family-history requirement; absence must not be used as a negative gate. | U39: Yes | V39: Moderate | W39: Family-history field; genetics and neurology notes | X39: family amyloidosis; TTR; familial neuropathy/cardiomyopathy | Y39: Strong background feature; never require it. | Z39: Small families, nonpenetrance, adoption and misdiagnosis can hide family history. | AA39: High | AB39: 4 | AC39: 5 | AD39: Tier 1 - highest | AE39: https://pubmed.ncbi.nlm.nih.gov/20301373/ | AF39: https://pubmed.ncbi.nlm.nih.gov/31907599/ | AG39: Detect once using canonical ID; phenotype overlays decide tier/role. | AH39: =IF(AND(E39<>"",D39<>""),"COVERED","MISSING") -> COVERED
A40: ATTRv | B40: V08 | C40: ATOM_V08 | D40: ATOM | E40: DETECT_ONCE | F40: Family history of unexplained adult-onset progressive neuropathy | G40: Genetic / family | H40: GENETICS / FAMILY HISTORY | I40: HEREDITARY | J40: Background risk | K40: Strongly supports ATTRv | L40: Tier 2 | M40: Yes | N40: Tier 2 | O40: ETIOLOGIC_CONTEXT | P40: Tier 2 | R40: Before or at symptom onset | S40: Family neuropathy + progressive painful/axonal PN + dysautonomia/CTS/cardiac signs | T40: No universal pedigree threshold. | U40: Yes | V40: Moderate | W40: Family-history section; neurology notes | X40: family history neuropathy; walking disability; unexplained neuropathy | Y40: Strong context feature. | Z40: Diabetes and other inherited neuropathies can cluster in families. | AA40: High | AB40: 4 | AC40: 5 | AD40: Tier 1 - highest | AE40: https://pubmed.ncbi.nlm.nih.gov/42584723/ | AF40: https://pubmed.ncbi.nlm.nih.gov/31907599/ | AG40: Detect once using canonical ID; phenotype overlays decide tier/role. | AH40: =IF(AND(E40<>"",D40<>""),"COVERED","MISSING") -> COVERED
A41: ATTRv | B41: V01 | C41: ATOM_V01 | D41: ATOM | E41: DETECT_ONCE | F41: Known pathogenic/likely pathogenic TTR variant from prior cascade or family testing | G41: Genetic / family | H41: GENETICS / FAMILY HISTORY | I41: HEREDITARY | J41: Background risk | K41: Strongly supports ATTRv | L41: Tier 1 | M41: Yes | N41: Tier 2 | O41: ETIOLOGIC_CONTEXT | P41: Tier 1 | R41: Can precede symptoms by years to decades | S41: Known carrier + any new compatible neurologic, autonomic, cardiac, renal or ocular change | T41: No universal age or biomarker threshold; monitor relative to variant/family predicted age of onset. | U41: Only if already known | V41: Moderate | W41: Genetics notes; family-history section; problem list | X41: pathogenic TTR variant; TTR carrier; familial amyloidosis | Y41: Very strong prior-risk feature; require new objective/clinical evidence before labeling active ATTRv. | Z41: Incomplete penetrance; asymptomatic carriers may remain disease-free for years. | AA41: High | AB41: 4 | AC41: 5 | AD41: Tier 1 - highest | AE41: https://pubmed.ncbi.nlm.nih.gov/20301373/ | AF41: https://pubmed.ncbi.nlm.nih.gov/35730447/ | AG41: Detect once using canonical ID; phenotype overlays decide tier/role. | AH41: =IF(AND(E41<>"",D41<>""),"COVERED","MISSING") -> COVERED
A42: ATTRv | B42: V09 | C42: AUTONOMIC_ORTHOSTASIS | D42: ATOM | E42: DETECT_ONCE | F42: Orthostatic hypotension / recurrent orthostatic intolerance | G42: Autonomic / cardiovascular | H42: AUTONOMIC / CARDIOLOGY | I42: AUTONOMIC | J42: Early autonomic red flag | K42: Supports ATTRv strongly | L42: Tier 2 | M42: Yes | N42: Tier 2 | O42: ORGAN_OR_PHENOTYPE_EVIDENCE | P42: Tier 2 | R42: Can occur early | S42: Orthostasis + painful/axonal PN + GI/urinary/sexual autonomic features | T42: Use standard clinical orthostatic definitions; medication context is essential. | U42: Yes | V42: High | W42: Vitals; problem list; cardiology/neurology notes | X42: orthostatic hypotension; postural BP drop; dizziness on standing | Y42: Strong supporting feature within an autonomic cluster. | Z42: Diuretics, dehydration, antihypertensives and diabetic autonomic neuropathy can mimic. | AA42: High | AB42: 4 | AC42: 4 | AD42: Tier 1 - highest | AE42: https://pubmed.ncbi.nlm.nih.gov/31907599/ | AF42: https://pubmed.ncbi.nlm.nih.gov/31473866/ | AG42: Detect once using canonical ID; phenotype overlays decide tier/role. | AH42: =IF(AND(E42<>"",D42<>""),"COVERED","MISSING") -> COVERED
A43: ATTRv | B43: V10 | C43: AUTONOMIC_GI_DYSMOTILITY | D43: ATOM | E43: DETECT_ONCE | F43: Alternating diarrhea/constipation, chronic diarrhea, or otherwise unexplained GI dysmotility | G43: Gastrointestinal / autonomic | H43: GASTROENTEROLOGY | I43: AUTONOMIC | J43: Early autonomic red flag | K43: Supports ATTRv strongly | L43: Tier 2 | M43: Yes | N43: Tier 2 | O43: ORGAN_OR_PHENOTYPE_EVIDENCE | P43: Tier 2 | R43: Can be early | S43: GI dysmotility + progressive PN + weight loss/orthostasis | T43: No symptom-frequency or 'no abdominal pain' criterion is validated. | U43: Yes | V43: High | W43: GI notes; problem list | X43: alternating diarrhea constipation; chronic diarrhea; dysmotility | Y43: Strong multisystem feature; focus on chronicity and unexplained pattern. | Z43: IBS, IBD, celiac disease, medications and AL can mimic; NotebookLM's 'absence of abdominal pain' is not a validated universal rule. | AA43: High | AB43: 4 | AC43: 4 | AD43: Tier 1 - highest | AE43: https://pubmed.ncbi.nlm.nih.gov/26663427/ | AF43: https://pubmed.ncbi.nlm.nih.gov/20301373/ | AG43: Detect once using canonical ID; phenotype overlays decide tier/role. | AH43: =IF(AND(E43<>"",D43<>""),"COVERED","MISSING") -> COVERED
A44: ATTRv | B44: V11 | C44: AUTONOMIC_GASTROPARESIS_EARLY_SATIETY | D44: ATOM | E44: DETECT_ONCE | F44: Gastroparesis / delayed gastric emptying / early satiety / recurrent nausea-vomiting | G44: Gastrointestinal / autonomic | H44: GASTROENTEROLOGY | I44: AUTONOMIC | J44: Early autonomic red flag | K44: Supports ATTRv strongly | L44: Tier 2 | M44: Yes | N44: Tier 2 | O44: ORGAN_OR_PHENOTYPE_EVIDENCE | P44: Tier 2 | R44: Can be early | S44: Gastroparesis/early satiety + neuropathy + orthostasis/weight loss | T44: No amyloid-specific gastric-emptying threshold. | U44: Yes | V44: High | W44: GI notes; gastric emptying report | X44: gastroparesis; delayed gastric emptying; early satiety | Y44: Strong supporting feature in autonomic cluster. | Z44: Diabetes, medications, functional GI disorders and AL are important mimics. | AA44: High | AB44: 4 | AC44: 4 | AD44: Tier 1 - highest | AE44: https://pubmed.ncbi.nlm.nih.gov/20301373/ | AF44: https://pubmed.ncbi.nlm.nih.gov/38174864/ | AG44: Detect once using canonical ID; phenotype overlays decide tier/role. | AH44: =IF(AND(E44<>"",D44<>""),"COVERED","MISSING") -> COVERED
A45: ATTRv | B45: V16 | C45: ATOM_V16 | D45: ATOM | E45: DETECT_ONCE | F45: Scalloped pupil / characteristic pupillary or iris abnormality | G45: Ocular | H45: OPHTHALMOLOGY | I45: OCULAR | J45: Strong subtype clue | K45: Strongly supports ATTRv | L45: Tier 1 | M45: Yes | N45: Tier 3 | O45: ORGAN_OR_PHENOTYPE_EVIDENCE | P45: Tier 1 | R45: Usually during ocular involvement | S45: Scalloped pupil + vitreous disease + neuropathy/family history | T45: No universal threshold; specialist documentation required. | U45: Yes | V45: Moderate | W45: Ophthalmology notes | X45: scalloped pupil; irregular pupil; amyloid iris | Y45: High discriminator, low sensitivity. | Z45: Low sensitivity and examiner dependence; other pupillary disorders exist. | AA45: High | AB45: 3 | AC45: 5 | AD45: Tier 1 - highest | AE45: https://pubmed.ncbi.nlm.nih.gov/42078187/ | AF45: https://pubmed.ncbi.nlm.nih.gov/20301373/ | AG45: Detect once using canonical ID; phenotype overlays decide tier/role. | AH45: =IF(AND(E45<>"",D45<>""),"COVERED","MISSING") -> COVERED
A46: ATTRv | B46: V12 | C46: SYSTEMIC_WEIGHT_LOSS | D46: ATOM | E46: DETECT_ONCE | F46: Unintentional weight loss / declining BMI or mBMI | G46: Systemic / GI | H46: GENERAL MEDICINE | I46: SYSTEMIC_CONTEXT | J46: Supporting systemic clue | K46: Supports ATTRv strongly | L46: Tier 3 | M46: No | N46: Tier 2 | O46: MODIFIER | P46: Tier 3 | R46: Can precede or accompany neuropathy | S46: Weight loss + GI dysmotility + neuropathy/autonomic signs | T46: No universal percentage-loss or mBMI cutoff for screening. | U46: Yes | V46: High | W46: Weights; nutrition notes; problem list | X46: unintentional weight loss; BMI decline; cachexia | Y46: Moderate-strong feature in a multisystem cluster. | Z46: AL, cancer, infection and many GI disorders also cause weight loss. | AA46: High | AB46: 4 | AC46: 4 | AD46: Tier 1 - highest | AE46: https://pubmed.ncbi.nlm.nih.gov/26663427/ | AF46: https://pubmed.ncbi.nlm.nih.gov/37869146/ | AG46: Detect once using canonical ID; phenotype overlays decide tier/role. | AH46: =IF(AND(E46<>"",D46<>""),"COVERED","MISSING") -> COVERED
A47: ATTRv | B47: V17 | C47: ATOM_V17 | D47: ATOM | E47: DETECT_ONCE | F47: Persistent microalbuminuria in a known TTR carrier | G47: Renal / carrier surveillance | H47: NEPHROLOGY | I47: RENAL | J47: Carrier conversion clue | K47: Supports ATTRv strongly | L47: Tier 2 | M47: No — modifier/context only | N47: Tier 2 | O47: ORGAN_OR_PHENOTYPE_EVIDENCE | P47: Tier 2 | R47: May precede overt neuropathy/nephropathy | S47: Known carrier + persistent microalbuminuria + subtle neurologic/autonomic change | T47: Do not generalize the p.Val50Met cohort cadence/cutoffs to all variants. | U47: Only if already known | V47: High | W47: Urine laboratory | X47: UACR; microalbumin; albuminuria | Y47: Useful carrier-surveillance feature; lower weight in unselected patients. | Z47: Evidence is old and genotype-specific; diabetes/HTN also cause albuminuria, so it is not a general-population ATTRv rule. | AA47: Moderate-High | AB47: 4 | AC47: 4 | AD47: Tier 2 - high | AE47: https://pubmed.ncbi.nlm.nih.gov/12584275/ | AF47: https://pubmed.ncbi.nlm.nih.gov/20301373/ | AG47: Detect once using canonical ID; phenotype overlays decide tier/role. | AH47: =IF(AND(E47<>"",D47<>""),"COVERED","MISSING") -> COVERED
... A57: ATTRv | B57: V22 | C57: ATOM_V22 | D57: ATOM | E57: DETECT_ONCE | F57: Nerve ultrasound showing abnormal proximal nerve/plexus enlargement or ATTR-pattern abnormalities | G57: Neurologic imaging | H57: NEUROLOGY | I57: NEURO | J57: Specialized early marker | K57: Supports ATTRv | L57: Tier 3 | M57: No | N57: Tier 3 | O57: ORGAN_OR_PHENOTYPE_EVIDENCE | P57: Tier 3 | R57: Potentially presymptomatic/early | S57: Ultrasound abnormality + carrier/family status + subtle PN | T57: No universal cross-sectional-area threshold. | U57: Only if already known | V57: Low | W57: Neurology ultrasound report | X57: nerve ultrasound; cross-sectional area; brachial plexus | Y57: Exploratory/specialized supporting feature. | Z57: Evidence is small and variant/center-specific; pattern is not validated for population screening. | AA57: Moderate | AB57: 3 | AC57: 4 | AD57: Tier 3 - moderate | AE57: https://www.sciencedirect.com/science/article/pii/S1388245725012982 | AF57: https://pubmed.ncbi.nlm.nih.gov/37869146/ | AG57: Detect once using canonical ID; phenotype overlays decide tier/role. | AH57: =IF(AND(E57<>"",D57<>""),"COVERED","MISSING") -> COVERED
...

Sheet Phenotype Overlays
A1: Sign_ID | B1: Canonical_Atom_or_Rule_ID | C1: Overlay_Phenotype | D1: Reasoning_Bucket | E1: Tier_or_Status | F1: Overlay_Role | G1: Gate_Eligible | H1: Priority_Behavior | I1: Source_Phenotype | J1: Implementation_Note
A2: WT01 | B2: RULE_ATTRWT_ORTHO_BEFORE_CARDIO | C2: ATTRwt | D2: TEMPORAL_COMPOSITE | E2: TEMPORAL | F2: TEMPORAL_RULE | G2: No — rule only | I2: ATTRwt | J2: Temporal sequence upgrades/qualifies a combination; it is not an independent bucket.
A3: WT04 | B3: ATOM_WT04 | C3: ATTRwt | D3: ORTHO | E3: Tier 1 | F3: POSITIVE_EVIDENCE | G3: Yes | I3: ATTRwt | J3: Best tier is taken within this bucket; tiers are never added.
A4: WT04 | B4: ATOM_WT04 | C4: GENERAL_AMYLOID | D4: ORTHO | E4: Tier 2 | F4: ORGAN_OR_PHENOTYPE_EVIDENCE | G4: Yes | I4: ATTRwt | J4: General amyloid gate uses independent buckets; etiology context may pair with one organ bucket.
A5: WT04 | B5: ATOM_WT04 | C5: ATTR_COMMON | D5: ORTHO | E5: Tier 1 | F5: ATTR_COMMON_EVIDENCE | G5: Yes | I5: ATTRwt | J5: Counts only in an explicitly allowed ATTR-common bucket combination.
A6: WT02 | B6: ORTHO_CTS_BILAT_RECURRENT | C6: ATTRwt | D6: ORTHO | E6: Tier 1 | F6: POSITIVE_EVIDENCE | G6: Yes | I6: ATTRwt | J6: Best tier is taken within this bucket; tiers are never added.
A7: WT02 | B7: ORTHO_CTS_BILAT_RECURRENT | C7: GENERAL_AMYLOID | D7: ORTHO | E7: Tier 2 | F7: ORGAN_OR_PHENOTYPE_EVIDENCE | G7: Yes | I7: ATTRwt | J7: General amyloid gate uses independent buckets; etiology context may pair with one organ bucket.
A8: WT02 | B8: ORTHO_CTS_BILAT_RECURRENT | C8: ATTR_COMMON | D8: ORTHO | E8: Tier 1 | F8: ATTR_COMMON_EVIDENCE | G8: Yes | I8: ATTRwt | J8: Counts only in an explicitly allowed ATTR-common bucket combination.
A9: WT03 | B9: ATOM_WT03 | C9: ATTRwt | D9: ORTHO | E9: Tier 1 | F9: POSITIVE_EVIDENCE | G9: Yes | I9: ATTRwt | J9: Best tier is taken within this bucket; tiers are never added.
A10: WT03 | B10: ATOM_WT03 | C10: GENERAL_AMYLOID | D10: ORTHO | E10: Tier 2 | F10: ORGAN_OR_PHENOTYPE_EVIDENCE | G10: Yes | I10: ATTRwt | J10: General amyloid gate uses independent buckets; etiology context may pair with one organ bucket.
A11: WT03 | B11: ATOM_WT03 | C11: ATTR_COMMON | D11: ORTHO | E11: Tier 1 | F11: ATTR_COMMON_EVIDENCE | G11: Yes | I11: ATTRwt | J11: Counts only in an explicitly allowed ATTR-common bucket combination.
A12: WT05 | B12: ORTHO_LUMBAR_STENOSIS | C12: ATTRwt | D12: ORTHO | E12: Tier 2 | F12: POSITIVE_EVIDENCE | G12: Yes | I12: ATTRwt | J12: Best tier is taken within this bucket; tiers are never added.
A13: WT05 | B13: ORTHO_LUMBAR_STENOSIS | C13: GENERAL_AMYLOID | D13: ORTHO | E13: Tier 2 | F13: ORGAN_OR_PHENOTYPE_EVIDENCE | G13: Yes | I13: ATTRwt | J13: General amyloid gate uses independent buckets; etiology context may pair with one organ bucket.
... A303: AL23 | B303: RULE_AL23 | C303: ATTRwt | D303: ORTHO | E303: ROUTE | F303: ROUTE_TO_ATTRWT | G303: No — route only | I303: AL | J303: This source row points to the target phenotype; do not double-count it as a new positive atom.

Sheet Combination Rules
A1: Phenotype | B1: Rule_ID | C1: Priority | D1: Rule_Type | E1: Required_Bucket_or_Class_1 | F1: Tier_Requirement_1 | G1: Required_Bucket_or_Class_2 | H1: Additional_Condition_or_Modifier | I1: Temporal_Required | J1: Output_Route | K1: Implementation_Notes
A2: GENERAL_AMYLOID | B2: GA01 | C2: Priority A | D2: COUNT_DISTINCT_BUCKETS | E2: Any 2 independent organ/phenotype buckets | F2: Tier 1-2 | H2: Allowed organ buckets: CARDIO, RENAL, NEURO, AUTONOMIC, ORTHO, OCULAR, MUCOSAL_CUTANEOUS, GI_HEPATIC | I2: No | J2: GENERAL_AMYLOID_REVIEW | K2: T3/T4 never supply the second bucket. Same biological process cannot be counted twice across source specialties.
A3: GENERAL_AMYLOID | B3: GA02 | C3: Priority A/B | D3: ORG_PLUS_ETIOLOGY | E3: 1 organ/phenotype bucket | F3: Tier 1-2 | G3: 1 etiologic-context bucket Tier 1-2 | H3: Etiology buckets: HEME_CLONAL, INFLAMMATORY_DRIVER, HEREDITARY | I3: No | J3: GENERAL_AMYLOID_REVIEW | K3: Etiology context alone never passes; it must pair with objective organ/phenotype evidence.
A4: ATTR_COMMON | B4: AC01 | C4: Priority A | D4: PAIR | E4: ORTHO | F4: Tier 1-2 | G4: CARDIO Tier 1-2 | I4: No | J4: ATTR_REVIEW | K4: Classic ATTRwt-shaped pair.
A5: ATTR_COMMON | B5: AC02 | C5: Priority A | D5: PAIR | E5: NEURO | F5: Tier 1-2 | G5: AUTONOMIC Tier 1-2 | I5: No | J5: ATTR_REVIEW | K5: Classic neuropathic ATTRv-shaped pair.
A6: ATTR_COMMON | B6: AC03 | C6: Priority A/B | D6: PAIR | E6: NEURO | F6: Tier 1-2 | G6: HEREDITARY Tier 1-2 | I6: No | J6: ATTR_REVIEW | K6: Strong hereditary neuropathy pattern.
A7: ATTR_COMMON | B7: AC04 | C7: Priority B | D7: PAIR | E7: NEURO | F7: Tier 1-2 | G7: CARDIO Tier 1-2 | I7: No | J7: ATTR_REVIEW | K7: Mixed neurologic-cardiac ATTR pattern.
A8: ATTR_COMMON | B8: AC05 | C8: Priority B | D8: PAIR | E8: CARDIO | F8: Tier 1-2 | G8: HEREDITARY Tier 1-2 | I8: No | J8: ATTR_REVIEW | K8: Allows cardiac-predominant ATTRv.
A9: ATTR_COMMON | B9: AC06 | C9: Priority B | D9: PAIR | E9: NEURO | F9: Tier 1-2 | G9: OCULAR Tier 1-2 | I9: No | J9: ATTR_REVIEW | K9: Ocular + neurologic ATTRv pattern.
A10: ATTR_COMMON | B10: AC07 | C10: Priority B/C | D10: PAIR | E10: ORTHO | F10: Tier 1-2 | G10: NEURO Tier 1-2 | I10: No | J10: ATTR_REVIEW | K10: ATTR common only; subtype requires wt/v-specific logic.
A11: ATTR_COMMON | B11: AC08 | C11: Priority B | D11: PAIR | E11: AUTONOMIC | F11: Tier 1-2 | G11: HEREDITARY Tier 1-2 | I11: No | J11: ATTR_REVIEW | K11: Hereditary autonomic pattern.
A12: ATTRwt | B12: WT_RULE_01 | C12: Priority A | D12: PAIR_TEMPORAL | E12: ORTHO | F12: Tier 1-2 | G12: CARDIO Tier 1-2 | H12: ORTHO first evidence precedes CARDIO first evidence; no hard universal year cutoff | I12: Yes | J12: ATTRWT_REVIEW | K12: Canonical ATTRwt rule. Temporal order strengthens priority but does not create another bucket.
A13: ATTRwt | B13: WT_RULE_02 | C13: Priority B | D13: PAIR | E13: ORTHO | F13: Tier 1-2 | G13: CARDIO Tier 1-2 | H13: Use when date quality is insufficient to prove sequence | I13: No | J13: ATTRWT_REVIEW | K13: Same phenotype with missing/uncertain chronology; rank below WT_RULE_01.
A14: ATTRv | B14: V_RULE_01 | C14: Priority A | D14: PAIR | E14: NEURO | F14: Tier 1-2 | G14: AUTONOMIC Tier 1-2 | I14: No | J14: ATTRV_REVIEW | K14: Canonical neuropathic/autonomic ATTRv.
A15: ATTRv | B15: V_RULE_02 | C15: Priority A | D15: PAIR | E15: NEURO | F15: Tier 1-2 | G15: HEREDITARY Tier 1-2 | I15: No | J15: ATTRV_REVIEW | K15: Progressive neuropathy + hereditary context.
A16: ATTRv | B16: V_RULE_03 | C16: Priority A/B | D16: PAIR | E16: NEURO | F16: Tier 1-2 | G16: OCULAR Tier 1-2 | I16: No | J16: ATTRV_REVIEW | K16: Neurologic + characteristic ocular phenotype.
A17: ATTRv | B17: V_RULE_04 | C17: Priority B | D17: PAIR | E17: NEURO | F17: Tier 1-2 | G17: CARDIO Tier 1-2 | I17: No | J17: ATTRV_REVIEW | K17: Mixed phenotype.
A18: ATTRv | B18: V_RULE_05 | C18: Priority B | D18: PAIR | E18: HEREDITARY | F18: Tier 1 | G18: CARDIO Tier 1-2 | I18: No | J18: ATTRV_REVIEW | K18: Allows cardiac-predominant hereditary disease without requiring neuropathy.
A19: ATTRv | B19: V_RULE_06 | C19: Priority B | D19: PAIR | E19: HEREDITARY | F19: Tier 1-2 | G19: AUTONOMIC Tier 1-2 | I19: No | J19: ATTRV_REVIEW | K19: Hereditary + dysautonomia.
A20: ATTRv | B20: V_RULE_07 | C20: Carrier conversion | D20: PAIR | E20: HEREDITARY | F20: Tier 1 | G20: RENAL Tier 1-2 | H20: Only for known carrier / cascade-testing context | I20: No | J20: ATTRV_CARRIER_REVIEW | K20: Carrier surveillance route; not equivalent to systemic ATTRv diagnosis.
A21: AL | B21: AL_RULE_01 | C21: Priority A | D21: PAIR | E21: HEME_CLONAL | F21: Tier 1-2 | G21: RENAL Tier 1-2 | I21: No | J21: AL_SAFETY_REVIEW | K21: Highest-yield clonal + renal phenotype.
A22: AL | B22: AL_RULE_02 | C22: Priority A/B | D22: PAIR | E22: HEME_CLONAL | F22: Tier 1-2 | G22: CARDIO Tier 1-2 | I22: No | J22: AL_SAFETY_REVIEW | K22: Clonal + cardiac amyloid phenotype.
A23: AL | B23: AL_RULE_03 | C23: Priority B | D23: PAIR | E23: HEME_CLONAL | F23: Tier 1-2 | G23: NEURO Tier 1-2 | I23: No | J23: AL_SAFETY_REVIEW | K23: Clonal + neuropathy.
A24: AL | B24: AL_RULE_04 | C24: Priority B | D24: PAIR | E24: HEME_CLONAL | F24: Tier 1-2 | G24: AUTONOMIC Tier 1-2 | I24: No | J24: AL_SAFETY_REVIEW | K24: Clonal + autonomic organ involvement.
A25: AL | B25: AL_RULE_05 | C25: Priority B | D25: PAIR | E25: HEME_CLONAL | F25: Tier 1-2 | G25: GI_HEPATIC Tier 1-2 | I25: No | J25: AL_SAFETY_REVIEW | K25: Clonal + GI/hepatic organ involvement.
A26: AL | B26: AL_RULE_06 | C26: Priority A | D26: PAIR_CLASS | E26: MUCOSAL_CUTANEOUS | F26: Tier 1 | G26: Any organ bucket Tier 1-2 | H26: Organ bucket may be RENAL/CARDIO/NEURO/AUTONOMIC/GI_HEPATIC | I26: No | J26: AL_SAFETY_REVIEW | K26: Macroglossia/purpura remain high-specificity but low-sensitivity clues.
A27: AL | B27: AL_RULE_07 | C27: Possible AL | D27: COUNT_DISTINCT_BUCKETS | E27: At least 3 organ buckets | F27: Tier 1-2 | H27: No HEME_CLONAL required for this rule | I27: No | J27: AL_MONOCLONAL_SCREEN | K27: Do not label AL; use as a funnel for appropriate monoclonal evaluation.
